Workbook
Name Выбранный_год: 'Финансовый отчет'!$K$2
Name Последние_метрики: OFFSET('Anglo American Platinum'!$B$6:$B$23,0,0,COUNTA('Anglo American Platinum'!$B$6:$B$23))
Name Последние_метрики: OFFSET('Impala Platinum'!$B$6:$B$21,0,0,COUNTA('Impala Platinum'!$B$6:$B$21))
Name Последние_метрики: OFFSET(Vale!$B$6:$B$21,0,0,COUNTA(Vale!$B$6:$B$21))
Name Последние_метрики: OFFSET(Норникель!$B$6:$B$24,0,0,COUNTA(Норникель!$B$6:$B$24))
Name Прошедшие_годы: OFFSET('Anglo American Platinum'!$B$3:$G$3,0,1,1,COUNTA('Anglo American Platinum'!$B$3:$G$3)-1)
Name Прошедшие_годы: OFFSET('Impala Platinum'!$B$3:$F$3,0,1,1,COUNTA('Impala Platinum'!$B$3:$F$3)-1)
Name Прошедшие_годы: OFFSET(Vale!$B$3:$F$3,0,1,1,COUNTA(Vale!$B$3:$F$3)-1)
Name Прошедшие_годы: OFFSET(Норникель!$B$3:$G$3,0,1,1,COUNTA(Норникель!$B$3:$G$3)-1)

Sheet Финансовый отчет
B2: ОТЧЁТ О ПРИБЫЛЯХ И УБЫТКАХ | K2: 2024
B3: Горно-металлургическая компания "Норильский никель"
B5: КЛЮЧЕВЫЕ МЕТРИКИ
B7: =Расчеты!B8 -> Итого выручка | D7: =Расчеты!B9 -> Валовая прибыль | F7: =Расчеты!B10 -> Прибыль от операционной деятельности | H7: =Расчеты!B11 -> Прибыль до налогообложения | J7: =Расчеты!B12 -> Прибыль за год
B8: =IFERROR(Расчеты!G8,"") | D8: =IFERROR(Расчеты!G9,"") | F8: =IFERROR(Расчеты!G10,"") | H8: =IFERROR(Расчеты!G11,"") | J8: =IFERROR(Расчеты!G12,"")
B9: =Расчеты!H8 | D9: =Расчеты!H9 | F9: =Расчеты!H10 | H9: =Расчеты!H11 | J9: =Расчеты!H12
B13: ВСЕ МЕТРИКИ
B15: МЕТРИКА | D15: ="ТЕКУЩИЙ ГОД ("&Выбранный_год&")" -> ТЕКУЩИЙ ГОД (2024) | F15: ="ПРОШЕДШИЙ ГОД ("&Выбранный_год-1&")" -> ПРОШЕДШИЙ ГОД (2023) | H15: ИЗМЕНЕНИЕ В % | I15: ТЕНДЕНЦИЯ ЗА 4 года
B16: Выручка: | H16: =IFERROR(D16/F16-1,"")
B17: =Расчеты!B16 -> Выручка от реализации металлов | D17: =IF($B17="","",Расчеты!G16) -> #N/A | F17: =IF($B17="","",Расчеты!F16) -> #N/A | H17: =IFERROR(D17/F17-1,"")
B18: =Расчеты!B17 -> Выручка от прочей реализации | D18: =IF($B18="","",Расчеты!G17) -> #N/A | F18: =IF($B18="","",Расчеты!F17) -> #N/A | H18: =IFERROR(D18/F18-1,"")
B19: =Расчеты!B18 -> Итого выручка | D19: =IF($B19="","",Расчеты!G18) -> #N/A | F19: =IF($B19="","",Расчеты!F18) -> #N/A | H19: =IFERROR(D19/F19-1,"")
B20: =Расчеты!B19 -> Себестоимость реализованных металлов | D20: =IF($B20="","",Расчеты!G19) -> #N/A | F20: =IF($B20="","",Расчеты!F19) -> #N/A | H20: =IFERROR(D20/F20-1,"")
B21: =Расчеты!B20 -> Себестоимость прочей реализации | D21: =IF($B21="","",Расчеты!G20) -> #N/A | F21: =IF($B21="","",Расчеты!F20) -> #N/A | H21: =IFERROR(D21/F21-1,"")
B22: =Расчеты!B21 -> Валовая прибыль | D22: =IF($B22="","",Расчеты!G21) -> #N/A | F22: =IF($B22="","",Расчеты!F21) -> #N/A | H22: =IFERROR(D22/F22-1,"")
B23: =Расчеты!B22 -> Административные расходы | D23: =IF($B23="","",Расчеты!G22) -> #N/A | F23: =IF($B23="","",Расчеты!F22) -> #N/A | H23: =IFERROR(D23/F23-1,"")
B24: =Расчеты!B23 -> Коммерческие расходы | D24: =IF($B24="","",Расчеты!G23) -> #N/A | F24: =IF($B24="","",Расчеты!F23) -> #N/A | H24: =IFERROR(D24/F24-1,"")
B25: =Расчеты!B24 -> Убыток от обесценения нефинансовых активов, нетто | D25: =IF($B25="","",Расчеты!G24) -> #N/A | F25: =IF($B25="","",Расчеты!F24) -> #N/A | H25: =IFERROR(D25/F25-1,"")
B26: =Расчеты!B26 -> Прочие операционные расходы, нетто | D26: =IF($B26="","",Расчеты!G26) -> #N/A | F26: =IF($B26="","",Расчеты!F26) -> #N/A | H26: =IFERROR(D26/F26-1,"")
B27: =Расчеты!B27 -> Прибыль от операционной деятельности | D27: =IF($B27="","",Расчеты!G27) -> #N/A | F27: =IF($B27="","",Расчеты!F27) -> #N/A | H27: =IFERROR(D27/F27-1,"")
B28: =Расчеты!B28 -> (Отрицательные)/положительные курсовые разницы, нетто | D28: =IF($B28="","",Расчеты!G28) -> #N/A | F28: =IF($B28="","",Расчеты!F28) -> #N/A | H28: =IFERROR(D28/F28-1,"")
B29: =Расчеты!B30 -> Финансовые расходы, нетто | D29: =IF($B29="","",Расчеты!G30) -> #N/A | F29: =IF($B29="","",Расчеты!F30) -> #N/A | H29: =IFERROR(D29/F29-1,"")
B30: =Расчеты!B31 -> Прибыль/(убыток) от выбытия дочерних организаций и зарубежных совместных операций | D30: =IF($B30="","",Расчеты!G31) -> #N/A | F30: =IF($B30="","",Расчеты!F31) -> #N/A | H30: =IFERROR(D30/F30-1,"")
B31: =Расчеты!B33 -> Прибыль от инвестиционной деятельности, нетто | D31: =IF($B31="","",Расчеты!G33) -> #N/A | F31: =IF($B31="","",Расчеты!F33) -> #N/A | H31: =IFERROR(D31/F31-1,"")
B32: =Расчеты!B34 -> Прибыль до налогообложения | D32: =IF($B32="","",Расчеты!G34) -> #N/A | F32: =IF($B32="","",Расчеты!F34) -> #N/A | H32: =IFERROR(D32/F32-1,"")
B33: =Расчеты!B35 -> Расходы по налогу на прибыль | D33: =IF($B33="","",Расчеты!G35) -> #N/A | F33: =IF($B33="","",Расчеты!F35) -> #N/A | H33: =IFERROR(D33/F33-1,"")
B34: =Расчеты!B36 -> Прибыль за год | D34: =IF($B34="","",Расчеты!G36) -> #N/A | F34: =IF($B34="","",Расчеты!F36) -> #N/A | H34: =IFERROR(D34/F34-1,"")

Sheet Коэффициенты
B2: КОЭФФИЦИЕНТЫ | C2: Норникель | G2: #VALUE! | H2: Vale | L2: #VALUE! | M2: Anglo American Platinum | Q2: #VALUE! | R2: Impala Platinum | V2: #VALUE! | W2: Комментарии
C3: 2021 | D3: 2022 | E3: 2023 | F3: 2024 | H3: 2021 | I3: 2022 | J3: 2023 | K3: 2024 | M3: 2021 | N3: 2022 | O3: 2023 | P3: 2024 | R3: 2021 | S3: 2022 | T3: 2023 | U3: 2024
B5: Коэффициенты ликвидности
B6: Оборотные активы | C6: =Норникель!C62 -> 9870 | D6: =Норникель!D62 -> 8403 | E6: =Норникель!E62 -> 7342 | F6: =Норникель!F62 -> 6845 | H6: =Vale!C56 -> 21384 | I6: =Vale!D56 -> 15526 | J6: =Vale!E56 -> 14767 | K6: =Vale!F56 -> 13481 | M6: ='Anglo American Platinum'!I62 -> 7169.5531 | N6: ='Anglo American Platinum'!J62 -> 5513.8291 | O6: ='Anglo American Platinum'!K62 -> 3691.4058 | P6: ='Anglo American Platinum'!L62 -> 3211.105 | R6: ='Impala Platinum'!I62 -> 3957.5419 | S6: ='Impala Platinum'!J62 -> 3698.8322 | T6: ='Impala Platinum'!K62 -> 3594.8011 | U6: ='Impala Platinum'!L62 -> 2781.0335
B7: Краткосрочные обязательства | C7: =Норникель!C98 -> 8083 | D7: =Норникель!D98 -> 7689 | E7: =Норникель!E98 -> 8831 | F7: =Норникель!F98 -> 5919 | H7: =Vale!C87 -> 14843 | I7: =Vale!D87 -> 13891 | J7: =Vale!E87 -> 14094 | K7: =Vale!F87 -> 13090 | M7: ='Anglo American Platinum'!I81 -> 3943.2961 | N7: ='Anglo American Platinum'!J81 -> 3568.3467 | O7: ='Anglo American Platinum'!K81 -> 2490.1326 | P7: ='Anglo American Platinum'!L81 -> 2479.4393 | R7: ='Impala Platinum'!I90 -> 1242.5279 | S7: ='Impala Platinum'!J90 -> 1019.4837 | T7: ='Impala Platinum'!K90 -> 937.50663 | U7: ='Impala Platinum'!L90 -> 926.0033
B8: Оборотный капитал | C8: =C6-C7 -> 1787 | D8: =D6-D7 -> 714 | E8: =E6-E7 -> -1489 | F8: =F6-F7 -> 926 | H8: =H6-H7 -> 6541 | I8: =I6-I7 -> 1635 | J8: =J6-J7 -> 673 | K8: =K6-K7 -> 391 | M8: =M6-M7 -> 3226.257 | N8: =N6-N7 -> 1945.4825 | O8: =O6-O7 -> 1201.2732 | P8: =P6-P7 -> 731.66575 | R8: =R6-R7 -> 2715.014 | S8: =S6-S7 -> 2679.3485 | T8: =T6-T7 -> 2657.2944 | U8: =U6-U7 -> 1855.0302
B9: Оборотные активы | C9: =Норникель!C62 -> 9870 | D9: =Норникель!D62 -> 8403 | E9: =Норникель!E62 -> 7342 | F9: =Норникель!F62 -> 6845 | H9: =Vale!C56 -> 21384 | I9: =Vale!D56 -> 15526 | J9: =Vale!E56 -> 14767 | K9: =Vale!F56 -> 13481 | M9: ='Anglo American Platinum'!I62 -> 7169.5531 | N9: ='Anglo American Platinum'!J62 -> 5513.8291 | O9: ='Anglo American Platinum'!K62 -> 3691.4058 | P9: ='Anglo American Platinum'!L62 -> 3211.105 | R9: ='Impala Platinum'!I62 -> 3957.5419 | S9: ='Impala Platinum'!J62 -> 3698.8322 | T9: ='Impala Platinum'!K62 -> 3594.8011 | U9: ='Impala Platinum'!L62 -> 2781.0335
B10: Авансы выданные | C10: =Норникель!C56 -> 111 | D10: =Норникель!D56 -> 192 | E10: =Норникель!E56 -> 173 | F10: =Норникель!F56 -> 135 | H10: =Vale!C50 -> 3914 | I10: =Vale!D50 -> 4319 | J10: =Vale!E50 -> 4197 | K10: =Vale!F50 -> 2358 | M10: ='Anglo American Platinum'!I58 -> 542.31844 | N10: ='Anglo American Platinum'!J58 -> 243.02397 | O10: ='Anglo American Platinum'!K58 -> 202.81167 | P10: ='Anglo American Platinum'!L58 -> 203.29852 | R10: ='Impala Platinum'!I60 -> 77.444134 | S10: ='Impala Platinum'!J60 -> 121.75784 | T10: ='Impala Platinum'!K60 -> 224.40318 | U10: ='Impala Platinum'!L60 -> 95.052226
B11: =Норникель!B58 -> Авансовые платежи по налогу на прибыль | C11: =Норникель!C58 -> 203 | D11: =Норникель!D58 -> 17 | E11: =Норникель!E58 -> 101 | F11: =Норникель!F58 -> 38 | H11: =Vale!C53 -> 862 | I11: =Vale!D53 -> 1272 | J11: =Vale!E53 -> 900 | K11: =Vale!F53 -> 1100 | M11: ='Anglo American Platinum'!I60 -> 169.76257 | N11: ='Anglo American Platinum'!J60 -> 196.68101 | O11: ='Anglo American Platinum'!K60 -> 122.33422 | P11: ='Anglo American Platinum'!L60 -> 90.324354 | R11: ='Impala Platinum'!I58 -> 74.301676 | S11: ='Impala Platinum'!J58 -> 32.575292 | T11: ='Impala Platinum'!K58 -> 56.180371 | U11: ='Impala Platinum'!L58 -> 43.485432
B12: Скорректированные оборотные активы | C12: =C9-C10-C11 -> 9556 | D12: =D9-D10-D11 -> 8194 | E12: =E9-E10-E11 -> 7068 | F12: =F9-F10-F11 -> 6672 | H12: =H9-H10-H11 -> 16608 | I12: =I9-I10-I11 -> 9935 | J12: =J9-J10-J11 -> 9670 | K12: =K9-K10-K11 -> 10023 | M12: =M9-M10-M11 -> 6457.4721 | N12: =N9-N10-N11 -> 5074.1242 | O12: =O9-O10-O11 -> 3366.2599 | P12: =P9-P10-P11 -> 2917.4821 | R12: =R9-R10-R11 -> 3805.7961 | S12: =S9-S10-S11 -> 3544.4991 | T12: =T9-T10-T11 -> 3314.2175 | U12: =U9-U10-U11 -> 2642.4959
B13: Краткосрочные обязательства | C13: =Норникель!C98 -> 8083 | D13: =Норникель!D98 -> 7689 | E13: =Норникель!E98 -> 8831 | F13: =Норникель!F98 -> 5919 | H13: =Vale!C87 -> 14843 | I13: =Vale!D87 -> 13891 | J13: =Vale!E87 -> 14094 | K13: =Vale!F87 -> 13090 | M13: ='Anglo American Platinum'!I81 -> 3943.2961 | N13: ='Anglo American Platinum'!J81 -> 3568.3467 | O13: ='Anglo American Platinum'!K81 -> 2490.1326 | P13: ='Anglo American Platinum'!L81 -> 2479.4393 | R13: ='Impala Platinum'!I90 -> 1242.5279 | S13: ='Impala Platinum'!J90 -> 1019.4837 | T13: ='Impala Platinum'!K90 -> 937.50663 | U13: ='Impala Platinum'!L90 -> 926.0033
B14: Коэффициент текущей ликвидности (CR) | C14: =C12/C13 -> 1.1822343 | D14: =D12/D13 -> 1.0656782 | E14: =E12/E13 -> 0.80036236 | F14: =F12/F13 -> 1.1272174 | H14: =H12/H13 -> 1.1189113 | I14: =I12/I13 -> 0.71521129 | J14: =J12/J13 -> 0.68610756 | K14: =K12/K13 -> 0.76569901 | M14: =M12/M13 -> 1.6375823 | N14: =N12/N13 -> 1.4219818 | O14: =O12/O13 -> 1.3518396 | P14: =P12/P13 -> 1.1766701 | R14: =R12/R13 -> 3.0629461 | S14: =S12/S13 -> 3.4767589 | T14: =T12/T13 -> 3.5351403 | U14: =U12/U13 -> 2.8536571
B15: Оборотные активы | C15: =Норникель!C62 -> 9870 | D15: =Норникель!D62 -> 8403 | E15: =Норникель!E62 -> 7342 | F15: =Норникель!F62 -> 6845 | H15: =Vale!C56 -> 21384 | I15: =Vale!D56 -> 15526 | J15: =Vale!E56 -> 14767 | K15: =Vale!F56 -> 13481 | M15: ='Anglo American Platinum'!I62 -> 7169.5531 | N15: ='Anglo American Platinum'!J62 -> 5513.8291 | O15: ='Anglo American Platinum'!K62 -> 3691.4058 | P15: ='Anglo American Platinum'!L62 -> 3211.105 | R15: ='Impala Platinum'!I62 -> 3957.5419 | S15: ='Impala Platinum'!J62 -> 3698.8322 | T15: ='Impala Platinum'!K62 -> 3594.8011 | U15: ='Impala Platinum'!L62 -> 2781.0335
B16: =Норникель!B54 -> Запасы | C16: =Норникель!C54 -> 3026 | D16: =Норникель!D54 -> 4945 | E16: =Норникель!E54 -> 3817 | F16: =Норникель!F54 -> 3114 | H16: =Vale!C52 -> 4377 | I16: =Vale!D52 -> 4482 | J16: =Vale!E52 -> 4684 | K16: =Vale!F52 -> 4605 | M16: ='Anglo American Platinum'!I57 -> 3595.1816 | N16: ='Anglo American Platinum'!J57 -> 1818.8691 | O16: ='Anglo American Platinum'!K57 -> 1291.9363 | P16: ='Anglo American Platinum'!L57 -> 1361.1325 | R16: ='Impala Platinum'!I56 -> 1585.9637 | S16: ='Impala Platinum'!J56 -> 1468.8998 | T16: ='Impala Platinum'!K56 -> 1290.1857 | U16: ='Impala Platinum'!L56 -> 1461.1325
B17: Краткосрочные обязательства | C17: =Норникель!C98 -> 8083 | D17: =Норникель!D98 -> 7689 | E17: =Норникель!E98 -> 8831 | F17: =Норникель!F98 -> 5919 | H17: =Vale!C87 -> 14843 | I17: =Vale!D87 -> 13891 | J17: =Vale!E87 -> 14094 | K17: =Vale!F87 -> 13090 | M17: ='Anglo American Platinum'!I81 -> 3943.2961 | N17: ='Anglo American Platinum'!J81 -> 3568.3467 | O17: ='Anglo American Platinum'!K81 -> 2490.1326 | P17: ='Anglo American Platinum'!L81 -> 2479.4393 | R17: ='Impala Platinum'!I90 -> 1242.5279 | S17: ='Impala Platinum'!J90 -> 1019.4837 | T17: ='Impala Platinum'!K90 -> 937.50663 | U17: ='Impala Platinum'!L90 -> 926.0033
B18: Коэффициент срочной ливидности (QR) | C18: =(C15-C16)/C17 -> 0.84671533 | D18: =(D15-D16)/D17 -> 0.44973339 | E18: =(E15-E16)/E17 -> 0.39916204 | F18: =(F15-F16)/F17 -> 0.63034296 | H18: =(H15-H16)/H17 -> 1.1457926 | I18: =(I15-I16)/I17 -> 0.79504715 | J18: =(J15-J16)/J17 -> 0.71541081 | K18: =(K15-K16)/K17 -> 0.67807487 | M18: =(M15-M16)/M17 -> 0.90644259 | N18: =(N15-N16)/N17 -> 1.0354824 | O18: =(O15-O16)/O17 -> 0.96359104 | P18: =(P15-P16)/P17 -> 0.74612536 | R18: =(R15-R16)/R17 -> 1.9086719 | S18: =(S15-S16)/S17 -> 2.1873154 | T18: =(T15-T16)/T17 -> 2.458239 | U18: =(U15-U16)/U17 -> 1.425374 | W18: слишком маленькие значения (не 1-2)
B20: Коэффициенты оборачиваемости
B21: Дебиторская задолженность | C21: =Норникель!C55 -> 468 | D21: =Норникель!D55 -> 846 | E21: =Норникель!E55 -> 764 | F21: =Норникель!F55 -> 1374 | H21: =Vale!C50 -> 3914 | I21: =Vale!D50 -> 4319 | J21: =Vale!E50 -> 4197 | K21: =Vale!F50 -> 2358 | M21: ='Anglo American Platinum'!I58 -> 542.31844 | N21: ='Anglo American Platinum'!J58 -> 243.02397 | O21: ='Anglo American Platinum'!K58 -> 202.81167 | P21: ='Anglo American Platinum'!L58 -> 203.29852 | R21: ='Impala Platinum'!I57 -> 510.3352 | S21: ='Impala Platinum'!J57 -> 381.62262 | T21: ='Impala Platinum'!K57 -> 600 | U21: ='Impala Platinum'!L57 -> 650.13744
B22: Скорректированная дебиторская задолженность на НДС | C22: =C21/1.2 -> 390 | D22: =D21/1.2 -> 705 | E22: =E21/1.2 -> 636.66667 | F22: =F21/1.2 -> 1145 | H22: =H21/1.18 -> 3316.9492 | I22: =I21/1.18 -> 3660.1695 | J22: =J21/1.18 -> 3556.7797 | K22: =K21/1.18 -> 1998.3051 | M22: =M21/1.14 -> 475.71793 | N22: =N21/1.14 -> 213.17892 | O22: =O21/1.14 -> 177.90497 | P22: =P21/1.14 -> 178.33203 | R22: =R21/1.14 -> 447.66245 | S22: =S21/1.14 -> 334.75668 | T22: =T21/1.14 -> 526.31579 | U22: =U21/1.14 -> 570.296
B23: Средняя скорректированная дебиторская задолженность | C23: =C22 -> 390 | D23: =AVERAGE(C22:D22) -> 547.5 | E23: =AVERAGE(D22:E22) -> 670.83333 | F23: =AVERAGE(E22:F22) -> 890.83333 | H23: =H22 -> 3316.9492 | I23: =AVERAGE(H22:I22) -> 3488.5593 | J23: =AVERAGE(I22:J22) -> 3608.4746 | K23: =AVERAGE(J22:K22) -> 2777.5424 | M23: =M22 -> 475.71793 | N23: =AVERAGE(M22:N22) -> 344.44842 | O23: =AVERAGE(N22:O22) -> 195.54195 | P23: =AVERAGE(O22:P22) -> 178.1185 | R23: =R22 -> 447.66245 | S23: =AVERAGE(R22:S22) -> 391.20957 | T23: =AVERAGE(S22:T22) -> 430.53624 | U23: =AVERAGE(T22:U22) -> 548.30589
B24: Выручка | C24: =Норникель!C9 -> 17852 | D24: =Норникель!D9 -> 16876 | E24: =Норникель!E9 -> 14409 | F24: =Норникель!F9 -> 12535 | H24: =Vale!C6 -> 54502 | I24: =Vale!D6 -> 43839 | J24: =Vale!E6 -> 41784 | K24: =Vale!F6 -> 38056 | M24: ='Anglo American Platinum'!I8 -> 13932.987 | N24: ='Anglo American Platinum'!J8 -> 10781.209 | O24: ='Anglo American Platinum'!K8 -> 7010.861 | P24: ='Anglo American Platinum'!L8 -> 5825.0668 | R24: ='Impala Platinum'!I6 -> 8413.961 | S24: ='Impala Platinum'!J6 -> 7774.77 | T24: ='Impala Platinum'!K6 -> 5998.5369 | U24: ='Impala Platinum'!L6 -> 4617.7445
B25: Период погашения дебиторской задолженности (дн.) | C25: =C23/C24*365 -> 7.9738965 | D25: =D23/D24*365 -> 11.841521 | E25: =E23/E24*365 -> 16.993141 | F25: =F23/F24*365 -> 25.939702 | H25: =H23/H24*365 -> 22.213615 | I25: =I23/I24*365 -> 29.045465 | J25: =J23/J24*365 -> 31.521473 | K25: =K23/K24*365 -> 26.639767 | M25: =M23/M24*365 -> 12.462298 | N25: =N23/N24*365 -> 11.661371 | O25: =O23/O24*365 -> 10.18032 | P25: =P23/P24*365 -> 11.160946 | R25: =R23/R24*365 -> 19.419723 | S25: =S23/S24*365 -> 18.366008 | T25: =T23/T24*365 -> 26.197343 | U25: =U23/U24*365 -> 43.339698
B26: Себестоимость реализованной продукции | C26: =-Норникель!C10+Норникель!C11 -> 4304 | D26: =-Норникель!D10+Норникель!D11 -> 5293 | E26: =-Норникель!E10+Норникель!E11 -> 5656 | F26: =-Норникель!F10+Норникель!F11 -> 5576 | H26: =-Vale!C7 -> 21729 | I26: =-Vale!D7 -> 24028 | J26: =-Vale!E7 -> 24089 | K26: =-Vale!F7 -> 24265 | M26: =-'Anglo American Platinum'!I9 -> 7107.5325 | N26: =-'Anglo American Platinum'!J9 -> 6148.3574 | O26: =-'Anglo American Platinum'!K9 -> 5828.3624 | P26: =-'Anglo American Platinum'!L9 -> 4851.3629 | R26: =-'Impala Platinum'!I7 -> 4942.8571 | S26: =-'Impala Platinum'!J7 -> 5062.2208 | T26: =-'Impala Platinum'!K7 -> 4741.4744 | U26: =-'Impala Platinum'!L7 -> 4325.5478
B27: =Норникель!B54 -> Запасы | C27: =Норникель!C54 -> 3026 | D27: =Норникель!D54 -> 4945 | E27: =Норникель!E54 -> 3817 | F27: =Норникель!F54 -> 3114 | H27: =Vale!C52 -> 4377 | I27: =Vale!D52 -> 4482 | J27: =Vale!E52 -> 4684 | K27: =Vale!F52 -> 4605 | M27: ='Anglo American Platinum'!I57 -> 3595.1816 | N27: ='Anglo American Platinum'!J57 -> 1818.8691 | O27: ='Anglo American Platinum'!K57 -> 1291.9363 | P27: ='Anglo American Platinum'!L57 -> 1361.1325 | R27: ='Impala Platinum'!I56 -> 1585.9637 | S27: ='Impala Platinum'!J56 -> 1468.8998 | T27: ='Impala Platinum'!K56 -> 1290.1857 | U27: ='Impala Platinum'!L56 -> 1461.1325
B28: Средняя величина запасов | C28: =C27 -> 3026 | D28: =AVERAGE(C27:D27) -> 3985.5 | E28: =AVERAGE(D27:E27) -> 4381 | F28: =AVERAGE(E27:F27) -> 3465.5 | H28: =H27 -> 4377 | I28: =AVERAGE(H27:I27) -> 4429.5 | J28: =AVERAGE(I27:J27) -> 4583 | K28: =AVERAGE(J27:K27) -> 4644.5 | M28: =M27 -> 3595.1816 | N28: =AVERAGE(M27:N27) -> 2707.0253 | O28: =AVERAGE(N27:O27) -> 1555.4027 | P28: =AVERAGE(O27:P27) -> 1326.5344 | R28: =R27 -> 1585.9637 | S28: =AVERAGE(R27:S27) -> 1527.4318 | T28: =AVERAGE(S27:T27) -> 1379.5427 | U28: =AVERAGE(T27:U27) -> 1375.6591
B29: Коэффициет оборачиваемости запасов | C29: =C26/C28 -> 1.4223397 | D29: =D26/D28 -> 1.3280642 | E29: =E26/E28 -> 1.2910294 | F29: =F26/F28 -> 1.609003 | H29: =H26/H28 -> 4.9643592 | I29: =I26/I28 -> 5.42454 | J29: =J26/J28 -> 5.2561641 | K29: =K26/K28 -> 5.224459 | M29: =M26/M28 -> 1.9769606 | N29: =N26/N28 -> 2.2712597 | O29: =O26/O28 -> 3.7471726 | P29: =P26/P28 -> 3.6571708 | R29: =R26/R28 -> 3.1166269 | S29: =S26/S28 -> 3.3142042 | T29: =T26/T28 -> 3.4369898 | U29: =U26/U28 -> 3.1443458
B30: Период оборачиваемости запасов (дн.) | C30: =365/C29 -> 256.61942 | D30: =365/D29 -> 274.8361 | E30: =365/E29 -> 282.72012 | F30: =365/F29 -> 226.84855 | H30: =365/H29 -> 73.524092 | I30: =365/I29 -> 67.286811 | J30: =365/J29 -> 69.442277 | K30: =365/K29 -> 69.863693 | M30: =365/M29 -> 184.62684 | N30: =365/N29 -> 160.70377 | O30: =365/O29 -> 97.406776 | P30: =365/P29 -> 99.803925 | R30: =365/R29 -> 117.11379 | S30: =365/S29 -> 110.13202 | T30: =365/T29 -> 106.19758 | U30: =365/U29 -> 116.08138 | W30: очень большие значения в сравнении с конкурентами
B31: Кредиторская задолженность | C31: =Норникель!C89 -> 2224 | D31: =Норникель!D89 -> 1381 | E31: =Норникель!E89 -> 1273 | F31: =Норникель!F89 -> 1209 | H31: =Vale!C74+Vale!C77 -> 5787 | I31: =Vale!D74+Vale!D77 -> 6133 | J31: =Vale!E74+Vale!E77 -> 6948 | K31: =Vale!F74+Vale!F77 -> 5777 | M31: ='Anglo American Platinum'!I82 -> 1753.4916 | N31: ='Anglo American Platinum'!J82 -> 1645.1752 | O31: ='Anglo American Platinum'!K82 -> 1301.8568 | P31: ='Anglo American Platinum'!L82 -> 1288.5102 | R31: ='Impala Platinum'!I83 -> 1130.5866 | S31: ='Impala Platinum'!J83 -> 948.24831 | T31: ='Impala Platinum'!K83 -> 850.98143 | U31: ='Impala Platinum'!L83 -> 813.52391
B32: Закупки в кредит (себестоимость реализованных товаров) | C32: =-Норникель!C10 -> 5057 | D32: =-Норникель!D10 -> 6103 | E32: =-Норникель!E10 -> 6344 | F32: =-Норникель!F10 -> 6232 | H32: =-Vale!C7 -> 21729 | I32: =-Vale!D7 -> 24028 | J32: =-Vale!E7 -> 24089 | K32: =-Vale!F7 -> 24265 | M32: =-'Anglo American Platinum'!I9 -> 7107.5325 | N32: =-'Anglo American Platinum'!J9 -> 6148.3574 | O32: =-'Anglo American Platinum'!K9 -> 5828.3624 | P32: =-'Anglo American Platinum'!L9 -> 4851.3629 | R32: =-'Impala Platinum'!I7 -> 4942.8571 | S32: =-'Impala Platinum'!J7 -> 5062.2208 | T32: =-'Impala Platinum'!K7 -> 4741.4744 | U32: =-'Impala Platinum'!L7 -> 4325.5478
B33: Период погашения кредиторской задолженности (дн.) | C33: =C31/C32*365 -> 160.52205 | D33: =D31/D32*365 -> 82.592987 | E33: =E31/E32*365 -> 73.241646 | F33: =F31/F32*365 -> 70.809531 | H33: =H31/H32*365 -> 97.209029 | I33: =I31/I32*365 -> 93.164017 | J33: =J31/J32*365 -> 105.2771 | K33: =K31/K32*365 -> 86.899032 | M33: =M31/M32*365 -> 90.048754 | N33: =N31/N32*365 -> 97.666563 | O33: =O31/O32*365 -> 81.528513 | P33: =P31/P32*365 -> 96.943111 | R33: =R31/R32*365 -> 83.486958 | S33: =S31/S32*365 -> 68.371304 | T33: =T31/T32*365 -> 65.508784 | U33: =U31/U32*365 -> 68.64708
B34: Операционный цикл денежных средств (дн.) | C34: =C25+C30-C33 -> 104.07127 | D34: =D25+D30-D33 -> 204.08464 | E34: =E25+E30-E33 -> 226.47162 | F34: =F25+F30-F33 -> 181.97872 | H34: =H25+H30-H33 -> -1.4713223 | I34: =I25+I30-I33 -> 3.1682595 | J34: =J25+J30-J33 -> -4.3133481 | K34: =K25+K30-K33 -> 9.6044279 | M34: =M25+M30-M33 -> 107.04039 | N34: =N25+N30-N33 -> 74.698582 | O34: =O25+O30-O33 -> 26.058583 | P34: =P25+P30-P33 -> 14.02176 | R34: =R25+R30-R33 -> 53.046558 | S34: =S25+S30-S33 -> 60.126723 | T34: =T25+T30-T33 -> 66.886138 | U34: =U25+U30-U33 -> 90.773998 | W34: очень большие значения в сравнении с конкурентами
B36: Коэффициенты рентабельности | W36: у всех все падает - не очень хороший знак, но примерно отраслевые значения
B37: PBIT | C37: =Норникель!C17 -> 9536 | D37: =Норникель!D17 -> 7581 | E37: =Норникель!E17 -> 5540 | F37: =Норникель!F17 -> 3574 | H37: =Vale!C14 -> 27693 | I37: =Vale!D14 -> 17208 | J37: =Vale!E14 -> 14205 | K37: =Vale!F14 -> 10788 | M37: ='Anglo American Platinum'!I10 -> 6825.4545 | N37: ='Anglo American Platinum'!J10 -> 4632.8515 | O37: ='Anglo American Platinum'!K10 -> 1182.4986 | P37: ='Anglo American Platinum'!L10 -> 973.7039 | R37: ='Impala Platinum'!I8 -> 3471.1039 | S37: ='Impala Platinum'!J8 -> 2712.5493 | T37: ='Impala Platinum'!K8 -> 1257.0625 | U37: ='Impala Platinum'!L8 -> 292.19669
B38: Активы | C38: =Норникель!C64 -> 23435 | D38: =Норникель!D64 -> 25795 | E38: =Норникель!E64 -> 23580 | F38: =Норникель!F64 -> 23170 | H38: =Vale!C71 -> 89442 | I38: =Vale!D71 -> 86894 | J38: =Vale!E71 -> 94186 | K38: =Vale!F71 -> 80152 | M38: ='Anglo American Platinum'!I63 -> 12580.237 | N38: ='Anglo American Platinum'!J63 -> 10873.632 | O38: ='Anglo American Platinum'!K63 -> 8976.9231 | P38: ='Anglo American Platinum'!L63 -> 9397.6361 | R38: ='Impala Platinum'!I63 -> 8832.0531 | S38: ='Impala Platinum'!J63 -> 9593.5464 | T38: ='Impala Platinum'!K63 -> 8985.9947 | U38: ='Impala Platinum'!L63 -> 7309.2358
B39: Краткосрочные обязательства | C39: =Норникель!C98 -> 8083 | D39: =Норникель!D98 -> 7689 | E39: =Норникель!E98 -> 8831 | F39: =Норникель!F98 -> 5919 | H39: =Vale!C89 -> 15198 | I39: =Vale!D89 -> 13891 | J39: =Vale!E89 -> 14655 | K39: =Vale!F89 -> 1309 | M39: ='Anglo American Platinum'!I81 -> 3943.2961 | N39: ='Anglo American Platinum'!J81 -> 3568.3467 | O39: ='Anglo American Platinum'!K81 -> 2490.1326 | P39: ='Anglo American Platinum'!L81 -> 2479.4393 | R39: ='Impala Platinum'!I90 -> 1242.5279 | S39: ='Impala Platinum'!J90 -> 1019.4837 | T39: ='Impala Platinum'!K90 -> 937.50663 | U39: ='Impala Platinum'!L90 -> 926.0033
B40: Задействованный капитал (CE) | C40: =C38-C39 -> 15352 | D40: =D38-D39 -> 18106 | E40: =E38-E39 -> 14749 | F40: =F38-F39 -> 17251 | H40: =H38-H39 -> 74244 | I40: =I38-I39 -> 73003 | J40: =J38-J39 -> 79531 | K40: =K38-K39 -> 78843 | M40: =M38-M39 -> 8636.9413 | N40: =N38-N39 -> 7305.2858 | O40: =O38-O39 -> 6486.7905 | P40: =P38-P39 -> 6918.1968 | R40: =R38-R39 -> 7589.5251 | S40: =S38-S39 -> 8574.0627 | T40: =T38-T39 -> 8048.4881 | U40: =U38-U39 -> 6383.2325
B41: Рентабельность задействованного капитала (ROCE) | C41: =C37/C40 -> 0.62115685 | D41: =D37/D40 -> 0.41870098 | E41: =E37/E40 -> 0.37561869 | F41: =F37/F40 -> 0.2071764 | H41: =H37/H40 -> 0.37299984 | I41: =I37/I40 -> 0.23571634 | J41: =J37/J40 -> 0.1786096 | K41: =K37/K40 -> 0.13682889 | M41: =M37/M40 -> 0.79026293 | N41: =N37/N40 -> 0.634178 | O41: =O37/O40 -> 0.18229332 | P41: =P37/P40 -> 0.14074533 | R41: =R37/R40 -> 0.45735456 | S41: =S37/S40 -> 0.31636686 | T41: =T37/T40 -> 0.15618616 | U41: =U37/U40 -> 0.045775661
B42: =Норникель!B12 -> Валовая прибыль | C42: =Норникель!C12 -> 12042 | D42: =Норникель!D12 -> 9963 | E42: =Норникель!E12 -> 7377 | F42: =Норникель!F12 -> 5647 | H42: =Vale!C8 -> 32773 | I42: =Vale!D8 -> 19811 | J42: =Vale!E8 -> 17695 | K42: =Vale!F8 -> 13791 | M42: ='Anglo American Platinum'!I10 -> 6825.4545 | N42: ='Anglo American Platinum'!J10 -> 4632.8515 | O42: ='Anglo American Platinum'!K10 -> 1182.4986 | P42: ='Anglo American Platinum'!L10 -> 973.7039 | R42: ='Impala Platinum'!I8 -> 3471.1039 | S42: ='Impala Platinum'!J8 -> 2712.5493 | T42: ='Impala Platinum'!K8 -> 1257.0625 | U42: ='Impala Platinum'!L8 -> 292.19669
B43: Выручка | C43: =Норникель!C9 -> 17852 | D43: =Норникель!D9 -> 16876 | E43: =Норникель!E9 -> 14409 | F43: =Норникель!F9 -> 12535 | H43: =Vale!C6 -> 54502 | I43: =Vale!D6 -> 43839 | J43: =Vale!E6 -> 41784 | K43: =Vale!F6 -> 38056 | M43: ='Anglo American Platinum'!I8 -> 13932.987 | N43: ='Anglo American Platinum'!J8 -> 10781.209 | O43: ='Anglo American Platinum'!K8 -> 7010.861 | P43: ='Anglo American Platinum'!L8 -> 5825.0668 | R43: ='Impala Platinum'!I6 -> 8413.961 | S43: ='Impala Platinum'!J6 -> 7774.77 | T43: ='Impala Platinum'!K6 -> 5998.5369 | U43: ='Impala Platinum'!L6 -> 4617.7445
B44: Маржа валовой прибыли (Gross profit margin) | C44: =C42/C43 -> 0.67454627 | D44: =D42/D43 -> 0.59036502 | E44: =E42/E43 -> 0.51197168 | F44: =F42/F43 -> 0.4504986 | H44: =H42/H43 -> 0.60131738 | I44: =I42/I43 -> 0.45190356 | J44: =J42/J43 -> 0.42348746 | K44: =K42/K43 -> 0.36238701 | M44: =M42/M43 -> 0.48987733 | N44: =N42/N43 -> 0.4297154 | O44: =O42/O43 -> 0.16866667 | P44: =P42/P43 -> 0.16715755 | R44: =R42/R43 -> 0.412541 | S44: =S42/S43 -> 0.34889126 | T44: =T42/T43 -> 0.20956151 | U44: =U42/U43 -> 0.063276928
...

Sheet Горизонтальный анализ
B2: ОТЧЁТ О ПРИБЫЛЯХ И УБЫТКАХ | C2: в миллионах долларов США | G2: Абсолютное изменение | J2: Темп роста | M2: Темп прироста
C3: 2021 | D3: 2022 | E3: 2023 | F3: 2024 | G3: 2021-2022 | H3: 2022-2023 | I3: 2023-2024 | J3: 2021-2022 | K3: 2022-2023 | L3: 2023-2024 | M3: 2021-2022 | N3: 2022-2023 | O3: 2023-2024
B5: Выручка
B6: Выручка от реализации металлов | C6: 17103 | D6: 16073 | E6: 13702 | F6: 11848 | G6: =D6-C6 -> -1030 | H6: =E6-D6 -> -2371 | I6: =F6-E6 -> -1854 | J6: =D6/C6 -> 0.93977665 | K6: =E6/D6 -> 0.85248553 | L6: =F6/E6 -> 0.86469129 | M6: =G6/C6 -> -0.060223353 | N6: =H6/D6 -> -0.14751447 | O6: =I6/E6 -> -0.13530871
B7: Выручка от прочей реализации | C7: 749 | D7: 803 | E7: 707 | F7: 687 | G7: =D7-C7 -> 54 | H7: =E7-D7 -> -96 | I7: =F7-E7 -> -20 | J7: =D7/C7 -> 1.0720961 | K7: =E7/D7 -> 0.88044832 | L7: =F7/E7 -> 0.97171146 | M7: =G7/C7 -> 0.072096128 | N7: =H7/D7 -> -0.11955168 | O7: =I7/E7 -> -0.028288543
B8: Итого выручка | C8: 17852 | D8: 16876 | E8: 14409 | F8: 12535 | G8: =D8-C8 -> -976 | H8: =E8-D8 -> -2467 | I8: =F8-E8 -> -1874 | J8: =D8/C8 -> 0.94532825 | K8: =E8/D8 -> 0.85381607 | L8: =F8/E8 -> 0.8699424 | M8: =G8/C8 -> -0.054671745 | N8: =H8/D8 -> -0.14618393 | O8: =I8/E8 -> -0.1300576 | P8: Выручка падает, себестоимость растет
B9: Себестоимость реализованных металлов | C9: -5057 | D9: -6103 | E9: -6344 | F9: -6232 | G9: =D9-C9 -> -1046 | H9: =E9-D9 -> -241 | I9: =F9-E9 -> 112 | J9: =D9/C9 -> 1.206842 | K9: =E9/D9 -> 1.0394888 | L9: =F9/E9 -> 0.98234552 | M9: =G9/C9 -> 0.206842 | N9: =H9/D9 -> 0.039488776 | O9: =I9/E9 -> -0.017654477
B10: Себестоимость прочей реализации | C10: -753 | D10: -810 | E10: -688 | F10: -656 | G10: =D10-C10 -> -57 | H10: =E10-D10 -> 122 | I10: =F10-E10 -> 32 | J10: =D10/C10 -> 1.0756972 | K10: =E10/D10 -> 0.84938272 | L10: =F10/E10 -> 0.95348837 | M10: =G10/C10 -> 0.075697211 | N10: =H10/D10 -> -0.15061728 | O10: =I10/E10 -> -0.046511628
B11: Валовая прибыль | C11: 12042 | D11: 9963 | E11: 7377 | F11: 5647 | G11: =D11-C11 -> -2079 | H11: =E11-D11 -> -2586 | I11: =F11-E11 -> -1730 | J11: =D11/C11 -> 0.82735426 | K11: =E11/D11 -> 0.74043963 | L11: =F11/E11 -> 0.76548733 | M11: =G11/C11 -> -0.17264574 | N11: =H11/D11 -> -0.25956037 | O11: =I11/E11 -> -0.23451267
B12: Административные расходы | C12: -989 | D12: -1353 | E12: -1093 | F12: -1046 | G12: =D12-C12 -> -364 | H12: =E12-D12 -> 260 | I12: =F12-E12 -> 47 | J12: =D12/C12 -> 1.3680485 | K12: =E12/D12 -> 0.80783444 | L12: =F12/E12 -> 0.95699909 | M12: =G12/C12 -> 0.36804853 | N12: =H12/D12 -> -0.19216556 | O12: =I12/E12 -> -0.043000915
B13: Коммерческие расходы | C13: 184 | D13: 261 | E13: 296 | F13: 408 | G13: =D13-C13 -> 77 | H13: =E13-D13 -> 35 | I13: =F13-E13 -> 112 | J13: =D13/C13 -> 1.4184783 | K13: =E13/D13 -> 1.1340996 | L13: =F13/E13 -> 1.3783784 | M13: =G13/C13 -> 0.41847826 | N13: =H13/D13 -> 0.13409962 | O13: =I13/E13 -> 0.37837838 | P13: Проблемы с логистикой: растут комерческие расходы и убыкти от обеценения нефти
B14: Убыток от обесценения нефинансовых активов, нетто | C14: 48 | D14: 90 | E14: 179 | F14: 441 | G14: =D14-C14 -> 42 | H14: =E14-D14 -> 89 | I14: =F14-E14 -> 262 | J14: =D14/C14 -> 1.875 | K14: =E14/D14 -> 1.9888889 | L14: =F14/E14 -> 2.4636872 | M14: =G14/C14 -> 0.875 | N14: =H14/D14 -> 0.98888889 | O14: =I14/E14 -> 1.4636872
B15: Прочие операционные расходы, нетто | C15: -1285 | D15: -678 | E15: -269 | F15: -178 | G15: =D15-C15 -> 607 | H15: =E15-D15 -> 409 | I15: =F15-E15 -> 91 | J15: =D15/C15 -> 0.52762646 | K15: =E15/D15 -> 0.39675516 | L15: =F15/E15 -> 0.66171004 | M15: =G15/C15 -> -0.47237354 | N15: =H15/D15 -> -0.60324484 | O15: =I15/E15 -> -0.33828996
B16: Прибыль от операционной деятельности | C16: 9536 | D16: 7581 | E16: 5540 | F16: 3574 | G16: =D16-C16 -> -1955 | H16: =E16-D16 -> -2041 | I16: =F16-E16 -> -1966 | J16: =D16/C16 -> 0.79498742 | K16: =E16/D16 -> 0.7307743 | L16: =F16/E16 -> 0.64512635 | M16: =G16/C16 -> -0.20501258 | N16: =H16/D16 -> -0.2692257 | O16: =I16/E16 -> -0.35487365
B17: (Отрицательные)/положительные курсовые разницы, нетто | C17: -53 | D17: 251 | E17: -1512 | F17: -343 | G17: =D17-C17 -> 304 | H17: =E17-D17 -> -1763 | I17: =F17-E17 -> 1169 | J17: =D17/C17 -> -4.7358491 | K17: =E17/D17 -> -6.0239044 | L17: =F17/E17 -> 0.22685185 | M17: =G17/C17 -> -5.7358491 | N17: =H17/D17 -> -7.0239044 | O17: =I17/E17 -> -0.77314815
B18: Финансовые расходы, нетто | C18: -279 | D18: -493 | E18: -567 | F18: -896 | G18: =D18-C18 -> -214 | H18: =E18-D18 -> -74 | I18: =F18-E18 -> -329 | J18: =D18/C18 -> 1.7670251 | K18: =E18/D18 -> 1.1501014 | L18: =F18/E18 -> 1.5802469 | M18: =G18/C18 -> 0.76702509 | N18: =H18/D18 -> 0.15010142 | O18: =I18/E18 -> 0.58024691
B19: Прибыль/(убыток) от выбытия дочерних организаций и зарубежных совместных операций | C19: 29 | D19: -110 | E19: 32 | F19: 0 | G19: =D19-C19 -> -139 | H19: =E19-D19 -> 142 | I19: =F19-E19 -> -32 | J19: =D19/C19 -> -3.7931034 | K19: =E19/D19 -> -0.29090909 | L19: =F19/E19 -> 0 | M19: =G19/C19 -> -4.7931034 | N19: =H19/D19 -> -1.2909091 | O19: =I19/E19 -> -1
B20: Прибыль от инвестиционной деятельности, нетто | C20: 52 | D20: 150 | E20: 41 | F20: 69 | G20: =D20-C20 -> 98 | H20: =E20-D20 -> -109 | I20: =F20-E20 -> 28 | J20: =D20/C20 -> 2.8846154 | K20: =E20/D20 -> 0.27333333 | L20: =F20/E20 -> 1.6829268 | M20: =G20/C20 -> 1.8846154 | N20: =H20/D20 -> -0.72666667 | O20: =I20/E20 -> 0.68292683
B21: Прибыль до налогообложения | C21: 9285 | D21: 7379 | E21: 3534 | F21: 2404 | G21: =D21-C21 -> -1906 | H21: =E21-D21 -> -3845 | I21: =F21-E21 -> -1130 | J21: =D21/C21 -> 0.79472267 | K21: =E21/D21 -> 0.47892668 | L21: =F21/E21 -> 0.68024901 | M21: =G21/C21 -> -0.20527733 | N21: =H21/D21 -> -0.52107332 | O21: =I21/E21 -> -0.31975099
B22: Расходы по налогу на прибыль | C22: -2311 | D22: -1525 | E22: -664 | F22: -589 | G22: =D22-C22 -> 786 | H22: =E22-D22 -> 861 | I22: =F22-E22 -> 75 | J22: =D22/C22 -> 0.65988749 | K22: =E22/D22 -> 0.43540984 | L22: =F22/E22 -> 0.88704819 | M22: =G22/C22 -> -0.34011251 | N22: =H22/D22 -> -0.56459016 | O22: =I22/E22 -> -0.11295181
B23: Прибыль за год | C23: 6974 | D23: 5854 | E23: 2870 | F23: 1815 | G23: =D23-C23 -> -1120 | H23: =E23-D23 -> -2984 | I23: =F23-E23 -> -1055 | J23: =D23/C23 -> 0.8394035 | K23: =E23/D23 -> 0.49026307 | L23: =F23/E23 -> 0.63240418 | M23: =G23/C23 -> -0.1605965 | N23: =H23/D23 -> -0.50973693 | O23: =I23/E23 -> -0.36759582
B25: ОТЧЁТ О ФИНАНСОВОМ ПОЛОЖЕНИИ | C25: в миллионах долларов США | G25: Абсолютное изменение | J25: Темп роста | M25: Темп прироста
C26: 2021 | D26: 2022 | E26: 2023 | F26: 2024 | G26: 2021-2022 | H26: 2022-2023 | I26: 2023-2024 | J26: 2021-2022 | K26: 2022-2023 | L26: 2023-2024 | M26: 2021-2022 | N26: 2022-2023 | O26: 2023-2024
B28: АКТИВЫ
B29: Внеоборотные активы
B30: Основные средства | C30: 12699 | D30: 16264 | E30: 15181 | F30: 15261 | G30: =D30-C30 -> 3565 | H30: =E30-D30 -> -1083 | I30: =F30-E30 -> 80 | J30: =D30/C30 -> 1.2807308 | K30: =E30/D30 -> 0.93341121 | L30: =F30/E30 -> 1.0052697 | M30: =G30/C30 -> 0.28073077 | N30: =H30/D30 -> -0.066588785 | O30: =I30/E30 -> 0.0052697451 | P30: Эффект пересчета в валюту представления
B31: Нематериальные активы | C31: 265 | D31: 302 | E31: 238 | F31: 206 | G31: =D31-C31 -> 37 | H31: =E31-D31 -> -64 | I31: =F31-E31 -> -32 | J31: =D31/C31 -> 1.1396226 | K31: =E31/D31 -> 0.78807947 | L31: =F31/E31 -> 0.86554622 | M31: =G31/C31 -> 0.13962264 | N31: =H31/D31 -> -0.21192053 | O31: =I31/E31 -> -0.13445378
B32: Инвестиции в ассоциированные организации и совместные предприятия | D32: 8 | E32: 76 | F32: 181 | G32: =D32-C32 -> 8 | H32: =E32-D32 -> 68 | I32: =F32-E32 -> 105 | K32: =E32/D32 -> 9.5 | L32: =F32/E32 -> 2.3815789 | N32: =H32/D32 -> 8.5 | O32: =I32/E32 -> 1.3815789
B33: Прочие финансовые активы | C33: 89 | D33: 113 | E33: 58 | F33: 57 | G33: =D33-C33 -> 24 | H33: =E33-D33 -> -55 | I33: =F33-E33 -> -1 | J33: =D33/C33 -> 1.2696629 | K33: =E33/D33 -> 0.51327434 | L33: =F33/E33 -> 0.98275862 | M33: =G33/C33 -> 0.26966292 | N33: =H33/D33 -> -0.48672566 | O33: =I33/E33 -> -0.017241379
B34: Отложенные налоговые активы | C34: 167 | D34: 340 | E34: 335 | F34: 328 | G34: =D34-C34 -> 173 | H34: =E34-D34 -> -5 | I34: =F34-E34 -> -7 | J34: =D34/C34 -> 2.0359281 | K34: =E34/D34 -> 0.98529412 | L34: =F34/E34 -> 0.97910448 | M34: =G34/C34 -> 1.0359281 | N34: =H34/D34 -> -0.014705882 | O34: =I34/E34 -> -0.020895522
B35: Прочие внеоборотные активы | C35: 345 | D35: 365 | E35: 350 | F35: 292 | G35: =D35-C35 -> 20 | H35: =E35-D35 -> -15 | I35: =F35-E35 -> -58 | J35: =D35/C35 -> 1.057971 | K35: =E35/D35 -> 0.95890411 | L35: =F35/E35 -> 0.83428571 | M35: =G35/C35 -> 0.057971014 | N35: =H35/D35 -> -0.04109589 | O35: =I35/E35 -> -0.16571429
B36: ИТОГО ВНЕОБОРОТНЫЕ АКТИВЫ | C36: 13565 | D36: 17392 | E36: 16238 | F36: 16325 | G36: =D36-C36 -> 3827 | H36: =E36-D36 -> -1154 | I36: =F36-E36 -> 87 | J36: =D36/C36 -> 1.2821231 | K36: =E36/D36 -> 0.93364765 | L36: =F36/E36 -> 1.0053578 | M36: =G36/C36 -> 0.28212311 | N36: =H36/D36 -> -0.066352346 | O36: =I36/E36 -> 0.0053578027
B37: Оборотные активы | P37: В целом, Норникель зачем-то в 22 достаточно много денег вложил в оборотные активы, а потом начал больше любить обычные денежки
B38: Запасы | C38: 3026 | D38: 4945 | E38: 3817 | F38: 3114 | G38: =D38-C38 -> 1919 | H38: =E38-D38 -> -1128 | I38: =F38-E38 -> -703 | J38: =D38/C38 -> 1.6341705 | K38: =E38/D38 -> 0.7718908 | L38: =F38/E38 -> 0.81582395 | M38: =G38/C38 -> 0.63417052 | N38: =H38/D38 -> -0.2281092 | O38: =I38/E38 -> -0.18417605
B39: Торговая и прочая дебиторская задолженность | C39: 468 | D39: 846 | E39: 764 | F39: 1374 | G39: =D39-C39 -> 378 | H39: =E39-D39 -> -82 | I39: =F39-E39 -> 610 | J39: =D39/C39 -> 1.8076923 | K39: =E39/D39 -> 0.90307329 | L39: =F39/E39 -> 1.7984293 | M39: =G39/C39 -> 0.80769231 | N39: =H39/D39 -> -0.096926714 | O39: =I39/E39 -> 0.79842932
B40: Авансы выданные и расходы будущих периодов | C40: 111 | D40: 192 | E40: 173 | F40: 135 | G40: =D40-C40 -> 81 | H40: =E40-D40 -> -19 | I40: =F40-E40 -> -38 | J40: =D40/C40 -> 1.7297297 | K40: =E40/D40 -> 0.90104167 | L40: =F40/E40 -> 0.78034682 | M40: =G40/C40 -> 0.72972973 | N40: =H40/D40 -> -0.098958333 | O40: =I40/E40 -> -0.21965318
B41: Прочие финансовые активы | C41: 43 | D41: 40 | E41: 3 | F41: 69 | G41: =D41-C41 -> -3 | H41: =E41-D41 -> -37 | I41: =F41-E41 -> 66 | J41: =D41/C41 -> 0.93023256 | K41: =E41/D41 -> 0.075 | L41: =F41/E41 -> 23 | M41: =G41/C41 -> -0.069767442 | N41: =H41/D41 -> -0.925 | O41: =I41/E41 -> 22
B42: Авансовые платежи по налогу на прибыль | C42: 203 | D42: 17 | E42: 101 | F42: 38 | G42: =D42-C42 -> -186 | H42: =E42-D42 -> 84 | I42: =F42-E42 -> -63 | J42: =D42/C42 -> 0.083743842 | K42: =E42/D42 -> 5.9411765 | L42: =F42/E42 -> 0.37623762 | M42: =G42/C42 -> -0.91625616 | N42: =H42/D42 -> 4.9411765 | O42: =I42/E42 -> -0.62376238
B43: Прочие налоги к возмещению | C43: 412 | D43: 477 | E43: 344 | F43: 292 | G43: =D43-C43 -> 65 | H43: =E43-D43 -> -133 | I43: =F43-E43 -> -52 | J43: =D43/C43 -> 1.157767 | K43: =E43/D43 -> 0.721174 | L43: =F43/E43 -> 0.84883721 | M43: =G43/C43 -> 0.15776699 | N43: =H43/D43 -> -0.278826 | O43: =I43/E43 -> -0.15116279
B44: Денежные средства и их эквиваленты | C44: 5547 | D44: 1882 | E44: 2139 | F44: 1822 | G44: =D44-C44 -> -3665 | H44: =E44-D44 -> 257 | I44: =F44-E44 -> -317 | J44: =D44/C44 -> 0.3392825 | K44: =E44/D44 -> 1.1365569 | L44: =F44/E44 -> 0.85179991 | M44: =G44/C44 -> -0.6607175 | N44: =H44/D44 -> 0.13655685 | O44: =I44/E44 -> -0.14820009
...

Sheet Вертикальный анализ
B2: ОТЧЁТ О ПРИБЫЛЯХ И УБЫТКАХ | D2: в миллионах долларов США | H2: Удельный вес к выручке
D3: 2021 | E3: 2022 | F3: 2023 | G3: 2024 | H3: 2021 | I3: 2022 | J3: 2023 | K3: 2024
B5: Выручка
B6: Выручка от реализации металлов | D6: 17103 | E6: 16073 | F6: 13702 | G6: 11848 | H6: =D6/D$8 -> 0.95804392 | I6: =E6/E$8 -> 0.95241763 | J6: =F6/F$8 -> 0.95093344 | K6: =G6/G$8 -> 0.94519346
B7: Выручка от прочей реализации | D7: 749 | E7: 803 | F7: 707 | G7: 687 | H7: =D7/D$8 -> 0.041956083 | I7: =E7/E$8 -> 0.047582365 | J7: =F7/F$8 -> 0.049066556 | K7: =G7/G$8 -> 0.054806542
B8: ИТОГО ВЫРУЧКА | D8: 17852 | E8: 16876 | F8: 14409 | G8: 12535 | H8: =D8/D$8 -> 1 | I8: =E8/E$8 -> 1 | J8: =F8/F$8 -> 1 | K8: =G8/G$8 -> 1 | L8: Выручка падает, себестоимость растет - очень грустная тенденция
B9: Себестоимость реализованных металлов | C9: Себестоимость реал. металлов | D9: 5057 | E9: 6103 | F9: 6344 | G9: 6232 | H9: =D9/D$8 -> 0.28327358 | I9: =E9/E$8 -> 0.36163783 | J9: =F9/F$8 -> 0.44028038 | K9: =G9/G$8 -> 0.49716793
B10: Себестоимость прочей реализации | C10: С-ть проч. реализации | D10: -753 | E10: -810 | F10: -688 | G10: -656 | H10: =D10/D$8 -> -0.042180148 | I10: =E10/E$8 -> -0.047997156 | J10: =F10/F$8 -> -0.047747935 | K10: =G10/G$8 -> -0.052333466
B11: Валовая прибыль | D11: 12042 | E11: 9963 | F11: 7377 | G11: 5647 | H11: =D11/D$8 -> 0.67454627 | I11: =E11/E$8 -> 0.59036502 | J11: =F11/F$8 -> 0.51197168 | K11: =G11/G$8 -> 0.4504986
B12: Административные расходы | C12: Адм. расходы | D12: -989 | E12: -1353 | F12: -1093 | G12: -1046 | H12: =D12/D$8 -> -0.055399955 | I12: =E12/E$8 -> -0.080173027 | J12: =F12/F$8 -> -0.075855368 | K12: =G12/G$8 -> -0.08344635
B13: Коммерческие расходы | C13: Комм. расходы | D13: -184 | E13: -261 | F13: -296 | G13: -408 | H13: =D13/D$8 -> -0.010306968 | I13: =E13/E$8 -> -0.01546575 | J13: =F13/F$8 -> -0.020542716 | K13: =G13/G$8 -> -0.032548863
B14: Убыток от обесценения нефинансовых активов, нетто | C14: Убыток от обесценения НФА | D14: -48 | E14: -90 | F14: -179 | G14: -441 | H14: =D14/D$8 -> -0.0026887744 | I14: =E14/E$8 -> -0.0053330173 | J14: =F14/F$8 -> -0.012422791 | K14: =G14/G$8 -> -0.035181492
B15: Прочие операционные расходы, нетто | C15: Прочие оп. расходы | D15: -1285 | E15: -678 | F15: -269 | G15: -178 | H15: =D15/D$8 -> -0.07198073 | I15: =E15/E$8 -> -0.040175397 | J15: =F15/F$8 -> -0.018668888 | K15: =G15/G$8 -> -0.014200239
B16: Прибыль от операционной деятельности | D16: 9536 | E16: 7581 | F16: 5540 | G16: 3574 | H16: =D16/D$8 -> 0.53416984 | I16: =E16/E$8 -> 0.44921782 | J16: =F16/F$8 -> 0.38448192 | K16: =G16/G$8 -> 0.28512166
B17: (Отрицательные)/положительные курсовые разницы, нетто | C17: Курсовые разницы | D17: -53 | E17: 251 | F17: -1512 | G17: -343 | H17: =D17/D$8 -> -0.002968855 | I17: =E17/E$8 -> 0.014873193 | J17: =F17/F$8 -> -0.10493442 | K17: =G17/G$8 -> -0.027363383
B18: Финансовые расходы, нетто | C18: Фин. расходы | D18: -279 | E18: -493 | F18: -567 | G18: -896 | H18: =D18/D$8 -> -0.015628501 | I18: =E18/E$8 -> -0.029213084 | J18: =F18/F$8 -> -0.039350406 | K18: =G18/G$8 -> -0.071479856
B19: Прибыль/(убыток) от выбытия дочерних организаций и зарубежных совместных операций | C19: Выбытие доч. орг. и заруб. операций | D19: 29 | E19: -110 | F19: 32 | G19: 0 | H19: =D19/D$8 -> 0.0016244678 | I19: =E19/E$8 -> -0.0065181323 | J19: =F19/F$8 -> 0.0022208342 | K19: =G19/G$8 -> 0
B20: Прибыль от инвестиционной деятельности, нетто | C20: Инвест. Деятельность | D20: 52 | E20: 150 | F20: 41 | G20: 69 | H20: =D20/D$8 -> 0.0029128389 | I20: =E20/E$8 -> 0.0088883622 | J20: =F20/F$8 -> 0.0028454438 | K20: =G20/G$8 -> 0.0055045872
B21: Прибыль до налогообложения | D21: 9285 | E21: 7379 | F21: 3534 | G21: 2404 | H21: =D21/D$8 -> 0.52010979 | I21: =E21/E$8 -> 0.43724816 | J21: =F21/F$8 -> 0.24526338 | K21: =G21/G$8 -> 0.19178301
B22: Расходы по налогу на прибыль | C22: Расх. по налогу на прибыль | D22: -2311 | E22: -1525 | F22: -664 | G22: -589 | H22: =D22/D$8 -> -0.12945328 | I22: =E22/E$8 -> -0.090365015 | J22: =F22/F$8 -> -0.04608231 | K22: =G22/G$8 -> -0.046988432
B23: Прибыль за год | D23: 6974 | E23: 5854 | F23: 2870 | G23: 1815 | H23: =D23/D$8 -> 0.39065651 | I23: =E23/E$8 -> 0.34688315 | J23: =F23/F$8 -> 0.19918107 | K23: =G23/G$8 -> 0.14479458
B25: ОТЧЁТ О ФИНАНСОВОМ ПОЛОЖЕНИИ | D25: в миллионах долларов США | H25: Удельный вес в итоговой величине | L25: Удельный вес в промежуточном значении
D26: 2021 | E26: 2022 | F26: 2023 | G26: 2024 | H26: 2021 | I26: 2022 | J26: 2023 | K26: 2024 | L26: 2021 | M26: 2022 | N26: 2023 | O26: 2024
B28: АКТИВЫ
B29: Внеоборотные активы
B30: Основные средства | C30: Основные средства | D30: 12699 | E30: 16264 | F30: 15181 | G30: 15261 | H30: =D30/D$47 -> 0.5418818 | I30: =E30/E$47 -> 0.63050979 | J30: =F30/F$47 -> 0.64380831 | K30: =G30/G$47 -> 0.65865343 | L30: =D30/D$36 -> 0.93615923 | M30: =E30/E$36 -> 0.93514259 | N30: =F30/F$36 -> 0.93490578 | O30: =G30/G$36 -> 0.93482389
B31: Нематериальные активы | C31: Нематериальные активы | D31: 265 | E31: 302 | F31: 238 | G31: 206 | H31: =D31/D$47 -> 0.011307873 | I31: =E31/E$47 -> 0.011707695 | J31: =F31/F$47 -> 0.010093299 | K31: =G31/G$47 -> 0.0088908071 | L31: =D31/D$36 -> 0.019535569 | M31: =E31/E$36 -> 0.017364305 | N31: =F31/F$36 -> 0.014656977 | O31: =G31/G$36 -> 0.012618683
B32: Инвестиции в ассоциированные организации и совместные предприятия | C32: Инвестиции в асс. орг. и совм. предпр. | E32: 8 | F32: 76 | G32: 181 | H32: =D32/D$47 -> 0 | I32: =E32/E$47 -> 0.00031013762 | J32: =F32/F$47 -> 0.0032230704 | K32: =G32/G$47 -> 0.0078118256 | L32: =D32/D$36 -> 0 | M32: =E32/E$36 -> 0.0004599816 | N32: =F32/F$36 -> 0.0046803794 | O32: =G32/G$36 -> 0.011087289
B33: Прочие финансовые активы | C33: Прочие финансовые активы | D33: 89 | E33: 113 | F33: 58 | G33: 57 | H33: =D33/D$47 -> 0.0037977384 | I33: =E33/E$47 -> 0.0043806939 | J33: =F33/F$47 -> 0.0024597116 | K33: =G33/G$47 -> 0.0024600777 | L33: =D33/D$36 -> 0.0065610026 | M33: =E33/E$36 -> 0.0064972401 | N33: =F33/F$36 -> 0.0035718685 | O33: =G33/G$36 -> 0.0034915773
B34: Отложенные налоговые активы | C34: Отложенные налоговые активы | D34: 167 | E34: 340 | F34: 335 | G34: 328 | H34: =D34/D$47 -> 0.0071260934 | I34: =E34/E$47 -> 0.013180849 | J34: =F34/F$47 -> 0.014206955 | K34: =G34/G$47 -> 0.014156237 | L34: =D34/D$36 -> 0.012311095 | M34: =E34/E$36 -> 0.019549218 | N34: =F34/F$36 -> 0.02063062 | O34: =G34/G$36 -> 0.020091884
B35: Прочие внеоборотные активы | C35: Прочие внеоборотные активы | D35: 345 | E35: 365 | F35: 350 | G35: 292 | H35: =D35/D$47 -> 0.01472157 | I35: =E35/E$47 -> 0.014150029 | J35: =F35/F$47 -> 0.014843087 | K35: =G35/G$47 -> 0.012602503 | L35: =D35/D$36 -> 0.0254331 | M35: =E35/E$36 -> 0.020986661 | N35: =F35/F$36 -> 0.021554379 | O35: =G35/G$36 -> 0.017886677
B36: ИТОГО ВНЕОБОРОТНЫЕ АКТИВЫ | D36: 13565 | E36: 17392 | F36: 16238 | G36: 16325 | H36: =D36/D$47 -> 0.57883508 | I36: =E36/E$47 -> 0.67423919 | J36: =F36/F$47 -> 0.68863444 | K36: =G36/G$47 -> 0.70457488 | L36: =D36/D$36 -> 1 | M36: =E36/E$36 -> 1 | N36: =F36/F$36 -> 1 | O36: =G36/G$36 -> 1
B37: Оборотные активы
B38: Запасы | C38: Запасы | D38: 3026 | E38: 4945 | F38: 3817 | G38: 3114 | H38: =D38/D$47 -> 0.12912311 | I38: =E38/E$47 -> 0.19170382 | J38: =F38/F$47 -> 0.16187447 | K38: =G38/G$47 -> 0.13439793 | L38: =D38/D$46 -> 0.30658561 | M38: =E38/E$46 -> 0.5884803 | N38: =F38/F$46 -> 0.51988559 | O38: =G38/G$46 -> 0.45493061
B39: Торговая и прочая дебиторская задолженность | C39: Торг. и пр. ДЗ | D39: 468 | E39: 846 | F39: 764 | G39: 1374 | H39: =D39/D$47 -> 0.01997013 | I39: =E39/E$47 -> 0.032797054 | J39: =F39/F$47 -> 0.032400339 | K39: =G39/G$47 -> 0.05930082 | L39: =D39/D$46 -> 0.047416413 | M39: =E39/E$46 -> 0.10067833 | N39: =F39/F$46 -> 0.10405884 | O39: =G39/G$46 -> 0.20073046 | P39: Дебиторка стабильно растет - немного странно
B40: Авансы выданные и расходы будущих периодов | C40: Ав. выданные и расх. буд. пер. | D40: 111 | E40: 192 | F40: 173 | G40: 135 | H40: =D40/D$47 -> 0.0047365052 | I40: =E40/E$47 -> 0.007443303 | J40: =F40/F$47 -> 0.007336726 | K40: =G40/G$47 -> 0.0058264998 | L40: =D40/D$46 -> 0.011246201 | M40: =E40/E$46 -> 0.022848983 | N40: =F40/F$46 -> 0.023563062 | O40: =G40/G$46 -> 0.019722425
B41: Прочие финансовые активы | C41: Прочие фин. активы | D41: 43 | E41: 40 | F41: 3 | G41: 69 | H41: =D41/D$47 -> 0.0018348624 | I41: =E41/E$47 -> 0.0015506881 | J41: =F41/F$47 -> 0.00012722646 | K41: =G41/G$47 -> 0.0029779888 | L41: =D41/D$46 -> 0.0043566363 | M41: =E41/E$46 -> 0.0047602047 | N41: =F41/F$46 -> 0.00040860801 | O41: =G41/G$46 -> 0.010080351
B42: Авансовые платежи по налогу на прибыль | C42: Ав. плат. по налогу на прибыль | D42: 203 | E42: 17 | F42: 101 | G42: 38 | H42: =D42/D$47 -> 0.0086622573 | I42: =E42/E$47 -> 0.00065904245 | J42: =F42/F$47 -> 0.0042832909 | K42: =G42/G$47 -> 0.0016400518 | L42: =D42/D$46 -> 0.020567376 | M42: =E42/E$46 -> 0.002023087 | N42: =F42/F$46 -> 0.01375647 | O42: =G42/G$46 -> 0.0055514974
B43: Прочие налоги к возмещению | C43: Пр. налоги к возмещению | D43: 412 | E43: 477 | F43: 344 | G43: 292 | H43: =D43/D$47 -> 0.017580542 | I43: =E43/E$47 -> 0.018491956 | J43: =F43/F$47 -> 0.014588634 | K43: =G43/G$47 -> 0.012602503 | L43: =D43/D$46 -> 0.041742655 | M43: =E43/E$46 -> 0.056765441 | N43: =F43/F$46 -> 0.046853718 | O43: =G43/G$46 -> 0.042658875
B44: Денежные средства и их эквиваленты | C44: ДС и их экв. | D44: 5547 | E44: 1882 | F44: 2139 | G44: 1822 | H44: =D44/D$47 -> 0.23669725 | I44: =E44/E$47 -> 0.072959876 | J44: =F44/F$47 -> 0.090712468 | K44: =G44/G$47 -> 0.078636167 | L44: =D44/D$46 -> 0.56200608 | M44: =E44/E$46 -> 0.22396763 | N44: =F44/F$46 -> 0.29133751 | O44: =G44/G$46 -> 0.26617969 | P44: В 2021 году запасов было мало, а денег много, а в 22 наоборот
...

Sheet Норникель
B2: КОНСОЛИДИРОВАННЫЙ
B3: ОТЧЁТ О ПРИБЫЛЯХ И УБЫТКАХ | D3: #VALUE!
B4: в миллионах долларов США | C4: За год, закончившийся 31 декабря
C5: 2021 | D5: 2022 | E5: 2023 | F5: 2024
B6: Выручка
B7: Выручка от реализации металлов | C7: 17103 | D7: 16073 | E7: 13702 | F7: 11848
B8: Выручка от прочей реализации | C8: 749 | D8: 803 | E8: 707 | F8: 687
B9: Итого выручка | C9: 17852 | D9: 16876 | E9: 14409 | F9: 12535
B10: Себестоимость реализованных металлов | C10: -5057 | D10: -6103 | E10: -6344 | F10: -6232
B11: Себестоимость прочей реализации | C11: -753 | D11: -810 | E11: -688 | F11: -656
B12: Валовая прибыль | C12: 12042 | D12: 9963 | E12: 7377 | F12: 5647
B13: Административные расходы | C13: -989 | D13: -1353 | E13: -1093 | F13: -1046
B14: Коммерческие расходы | C14: -184 | D14: -261 | E14: -296 | F14: -408
B15: Убыток от обесценения нефинансовых активов, нетто | C15: -48 | D15: -90 | E15: -179 | F15: -441
B16: Прочие операционные расходы, нетто | C16: -1285 | D16: -678 | E16: -269 | F16: -178
B17: Прибыль от операционной деятельности | C17: 9536 | D17: 7581 | E17: 5540 | F17: 3574
B18: (Отрицательные)/положительные курсовые разницы, нетто | C18: -53 | D18: 251 | E18: -1512 | F18: -343
... B24: Прибыль за год | C24: 6974 | D24: 5854 | E24: 2870 | F24: 1815
B26: КОНСОЛИДИРОВАННЫЙ
B27: ОТЧЁТ О СОВОКУПНОМ ДОХОДЕ | D27: #VALUE!
B28: в миллионах долларов США | C28: За год, закончившийся 31 декабря
C29: 2021 | D29: 2022 | E29: 2023 | F29: 2024
B30: Прибыль за год | C30: 6974 | D30: 5854 | E30: 2870 | F30: 1815
B31: Прочий совокупный доход/(расход)
B32: Статьи, которые реклассифицированы или впоследствии могут быть реклассифицированы в состав прибыли или убытка:
B33: Реклассификация резерва курсовых разниц по выбывшим зарубежным операциям, в состав прибыли или убытка | C33: 20 | D33: 0 | E33: 0 | F33: 0
B34: Эффект пересчета зарубежных операций и прочие резервы | C34: -2 | D34: 29 | E34: -31 | F34: -4
B35: Статьи, которые впоследствии не будут реклассифицированы в состав прибыли или убытка:
B36: Эффект пересчета в валюту представления | C36: 80 | D36: 891 | E36: -1825 | F36: -1016
B37: Прочий совокупный (расход)/доход за период с учетом эффекта налогообложения | C37: 98 | D37: 920 | E37: (1 856) | F37: (1 020)
B38: Общий совокупный доход за период с учетом эффекта налогообложения | C38: 7072 | D38: 6774 | E38: 1014 | F38: 795
B40: КОНСОЛИДИРОВАННЫЙ
B41: ОТЧЁТ О ФИНАНСОВОМ ПОЛОЖЕНИИ | D41: #VALUE!
B42: в миллионах долларов США | C42: За год, закончившийся 31 декабря
C43: 2021 | D43: 2022 | E43: 2023 | F43: 2024
B44: АКТИВЫ
B45: Внеоборотные активы
B46: Основные средства | C46: 12699 | D46: 16264 | E46: 15181 | F46: 15261
B47: Нематериальные активы | C47: 265 | D47: 302 | E47: 238 | F47: 206
B48: Инвестиции в ассоциированные организации и совместные предприятия | D48: 8 | E48: 76 | F48: 181
...

Sheet Vale
B2: КОНСОЛИДИРОВАННЫЙ
B3: ОТЧЁТ О ПРИБЫЛЯХ И УБЫТКАХ | D3: #VALUE!
B4: в миллионах долларов США | C4: За год, закончившийся 31 декабря
C5: 2021 | D5: 2022 | E5: 2023 | F5: 2024
B6: Выручка | C6: 54502 | D6: 43839 | E6: 41784 | F6: 38056
B7: Себестоимость проданных товаров и оказанных услуг | C7: -21729 | D7: -24028 | E7: -24089 | F7: -24265
B8: Валовая прибыль | C8: 32773 | D8: 19811 | E8: 17695 | F8: 13791
B9: Коммерческие и административные расходы | C9: -481 | D9: -515 | E9: -553 | F9: -622
B10: Исследования и разработки | C10: -549 | D10: -660 | E10: -723 | F10: -790
B11: Подготовка к эксплуатации и остановка производства | C11: -648 | D11: -479 | E11: -450 | F11: -403
B12: Убыток от обесценения нефинансовых активов нетто | C12: -426 | D12: 773 | E12: -266 | F12: 301
B13: Прочие операционные расходы нетто | C13: -2976 | D13: -1722 | E13: -1498 | F13: -1489
B14: Прибыль от операционной деятельности | C14: 27693 | D14: 17208 | E14: 14205 | F14: 10788
B15: Финансовые доходы | C15: 337 | D15: 520 | E15: 432 | F15: 422
B16: Финансовые расходы нетто | C16: -1249 | D16: -1179 | E16: -1459 | F16: -1473
B17: Результаты участия в акционерном капитале и прочие результаты деятельности ассоциированных компаний и совместных предприятий | C17: -1271 | D17: 2927 | E17: -919 | F17: -2772
... B21: Прибыль за год | C21: 24844 | D21: 16810 | E21: 8105 | F21: 6166
B23: КОНСОЛИДИРОВАННЫЙ
B24: ОТЧЁТ О СОВОКУПНОМ ДОХОДЕ | D24: #VALUE!
B25: в миллионах долларов США | C25: За год, закончившийся 31 декабря
C26: 2021 | D26: 2022 | E26: 2023 | F26: 2024
B27: Прибыль за год | C27: 22468 | D27: 18870 | E27: 8105 | F27: 5975
B28: Прочий совокупный доход/(расход)
B29: Статьи которые реклассифицированы или впоследствии могут быть реклассифицированы в состав прибыли или убытка:
B30: Эффект пересчета в валюту представления | C30: 918 | D30: -1306 | E30: -522 | F30: 2237
B31: Хеджирование чистых инвестиций | C31: -118 | D31: 81 | E31: 139 | F31: -500
B32: Хеджирование денежных потоков | C32: 3 | D32: 19 | E32: -19 | F32: -
B33: Реклассификация накопленной корректировки при пересчете в отчет о прибылях и убытках | C33: -4749 | D33: -483 | E33: - | F33: -1115
B34: Статьи которые впоследствии не будут реклассифицированы в состав прибыли или убытка:
B35: Корректировки при пересчете данных Материнской компании | C35: -2174 | D35: 2259 | E35: 2966 | F35: -9172
B36: Обязательства по пенсионным выплатам | C36: 475 | D36: 269 | E36: -68 | F36: 102
B37: Корректировки справедливой стоимости долей участия в капитале оцениваемых по справедливой стоимости через прочий совокупный доход | C37: 397 | D37: - | E37: 13 | F37: -
C38: -1302 | D38: 2528 | E38: 2911 | F38: -9070
B39: Прочий совокупный (расход)/доход за период с учетом эффекта налогообложения | C39: 17220 | D39: -2473 | E39: 10614 | F39: 15362
B40: Общий совокупный доход за период с учетом эффекта налогообложения | C40: 17199 | D40: -2189 | E40: 10489 | F40: 15282
B42: КОНСОЛИДИРОВАННЫЙ
B43: ОТЧЁТ О ФИНАНСОВОМ ПОЛОЖЕНИИ | D43: #VALUE!
B44: в миллионах долларов США | C44: За год, закончившийся 31 декабря
C45: 2021 | D45: 2022 | E45: 2023 | F45: 2024
B46: АКТИВЫ
...

Sheet Anglo American Platinum
B2: КОНСОЛИДИРОВАННЫЙ | H2: КОНСОЛИДИРОВАННЫЙ
B3: ОТЧЁТ О ПРИБЫЛЯХ И УБЫТКАХ | D3: #VALUE! | H3: ОТЧЁТ О ПРИБЫЛЯХ И УБЫТКАХ | J3: #VALUE!
B4: в миллионах южноафриканских рэнд | C4: За год, закончившийся 31 декабря | H4: в миллионах долларов США (пересчёт по среднегодовому курсу) | I4: За год, закончившийся 31 декабря
C5: 2021 | D5: 2022 | E5: 2023 | F5: 2024 | I5: 2021 | J5: 2022 | K5: 2023 | L5: 2024 | N5: Курс USD
B6: Валовой доход | C6: 214580 | D6: 164104 | E6: 124604 | F6: 109007 | H6: Валовой доход | I6: =C6/$O$16 -> 13933.766 | J6: =D6/$O$15 -> 10782.129 | K6: =E6/$O$14 -> 7012.0428 | L6: =F6/$O$13 -> 5826.1358 | N6: Year-end rate (R/USD):
B7: Выплаченные комиссионные | C7: -12 | D7: -14 | E7: -21 | F7: -20 | H7: Выплаченные комиссионные | I7: =C7/$O$16 -> -0.77922078 | J7: =D7/$O$15 -> -0.91984231 | K7: =E7/$O$14 -> -1.181767 | L7: =F7/$O$13 -> -1.0689471 | N7: 2024 | O7: 18.19
B8: Итого выручка | C8: 214568 | D8: 164090 | E8: 124583 | F8: 108987 | H8: Итого выручка | I8: =C8/$O$16 -> 13932.987 | J8: =D8/$O$15 -> 10781.209 | K8: =E8/$O$14 -> 7010.861 | L8: =F8/$O$13 -> 5825.0668 | N8: 2023 | O8: 18.85
B9: Себестоимость продаж | C9: -109456 | D9: -93578 | E9: -103570 | F9: -90769 | H9: Себестоимость продаж | I9: =C9/$O$16 -> -7107.5325 | J9: =D9/$O$15 -> -6148.3574 | K9: =E9/$O$14 -> -5828.3624 | L9: =F9/$O$13 -> -4851.3629 | N9: 2022 | O9: 16.27
B10: Валовая прибыль | C10: 105112 | D10: 70512 | E10: 21013 | F10: 18218 | H10: Валовая прибыль | I10: =C10/$O$16 -> 6825.4545 | J10: =D10/$O$15 -> 4632.8515 | K10: =E10/$O$14 -> 1182.4986 | L10: =F10/$O$13 -> 973.7039 | N10: 2021 | O10: 14.32
B11: Финансовый доход | C11: 713 | D11: 972 | E11: 1198 | F11: 984 | H11: Финансовый доход | I11: =C11/$O$16 -> 46.298701 | J11: =D11/$O$15 -> 63.863338 | K11: =E11/$O$14 -> 67.416995 | L11: =F11/$O$13 -> 52.592197
B12: Полученные дивиденды | C12: 14 | D12: — | E12: — | F12: — | H12: Полученные дивиденды | I12: =C12/$O$16 -> 0.90909091 | J12: — | K12: — | L12: — | N12: Average rate:
B13: Прочие доходы | C13: 2447 | D13: 896 | E13: 121 | F13: 42 | H13: Прочие доходы | I13: =C13/$O$16 -> 158.8961 | J13: =D13/$O$15 -> 58.869908 | K13: =E13/$O$14 -> 6.809229 | L13: =F13/$O$13 -> 2.2447889 | N13: 2024 | O13: 18.71
B14: Резерв на покрытие ожидаемых кредитных убытков | C14: -125 | D14: 195 | E14: -17 | F14: -30 | H14: Резерв на покрытие ожидаемых кредитных убытков | I14: =C14/$O$16 -> -8.1168831 | J14: =D14/$O$15 -> 12.812089 | K14: =E14/$O$14 -> -0.95666854 | L14: =F14/$O$13 -> -1.6034206 | N14: 2023 | O14: 17.77
B15: Оценка справедливой стоимости финансовых активов и обязательств и инвестиций в экологические трасты | C15: 4494 | D15: -2384 | E15: 607 | F15: -276 | H15: Оценка справедливой стоимости финансовых активов и обязательств и инвестиций в экологические трасты | I15: =C15/$O$16 -> 291.81818 | J15: =D15/$O$15 -> -156.63601 | K15: =E15/$O$14 -> 34.158694 | L15: =F15/$O$13 -> -14.75147 | N15: 2022 | O15: 15.22
B16: Финансовые расходы | C16: -357 | D16: -382 | E16: -645 | F16: -1142 | H16: Финансовые расходы | I16: =C16/$O$16 -> -23.181818 | J16: =D16/$O$15 -> -25.098555 | K16: =E16/$O$14 -> -36.29713 | L16: =F16/$O$13 -> -61.036879 | N16: 2021 | O16: 15.4
B17: Доля (убытка)/ прибыли от предприятий, учитываемых в составе собственного капитала | C17: 952 | D17: -227 | E17: 219 | F17: -1296 | H17: Доля (убытка)/ прибыли от предприятий, учитываемых в составе собственного капитала | I17: =C17/$O$16 -> 61.818182 | J17: =D17/$O$15 -> -14.914586 | K17: =E17/$O$14 -> 12.324142 | L17: =F17/$O$13 -> -69.267771
B18: Расходы на развитие рынка и продвижение продукции | C18: -966 | D18: -1342 | E18: -1800 | F18: -1343 | H18: Расходы на развитие рынка и продвижение продукции | I18: =C18/$O$16 -> -62.727273 | J18: =D18/$O$15 -> -88.173456 | K18: =E18/$O$14 -> -101.29432 | L18: =F18/$O$13 -> -71.779797
B19: Списание незавершенных капитальных работ и основных средств | C19: -27 | D19: -456 | E19: -177 | F19: -1868 | H19: Списание незавершенных капитальных работ и основных средств | I19: =C19/$O$16 -> -1.7532468 | J19: =D19/$O$15 -> -29.960578 | K19: =E19/$O$14 -> -9.9606078 | L19: =F19/$O$13 -> -99.839658
B20: Прочие расходы | C20: -3946 | D20: -1016 | E20: -2410 | F20: -3610 | H20: Прочие расходы | I20: =C20/$O$16 -> -256.23377 | J20: =D20/$O$15 -> -66.754271 | K20: =E20/$O$14 -> -135.62183 | L20: =F20/$O$13 -> -192.94495
B21: Прибыль до налогообложения | C21: 108311 | D21: 66768 | E21: 18109 | F21: 9679 | H21: Прибыль до налогообложения | I21: =C21/$O$16 -> 7033.1818 | J21: =D21/$O$15 -> 4386.8594 | K21: =E21/$O$14 -> 1019.0771 | L21: =F21/$O$13 -> 517.31694
B22: Расходы по налогу на прибыль | C22: -29290 | D22: -17472 | E22: -4663 | F22: -2286 | H22: Расходы по налогу на прибыль | I22: =C22/$O$16 -> -1901.9481 | J22: =D22/$O$15 -> -1147.9632 | K22: =E22/$O$14 -> -262.40855 | L22: =F22/$O$13 -> -122.18065
B23: Прибыль за год | C23: 79021 | D23: 49296 | E23: 13446 | F23: 7393 | H23: Прибыль за год | I23: =C23/$O$16 -> 5131.2338 | J23: =D23/$O$15 -> 3238.8962 | K23: =E23/$O$14 -> 756.66854 | L23: =F23/$O$13 -> 395.13629
B25: КОНСОЛИДИРОВАННЫЙ | H25: КОНСОЛИДИРОВАННЫЙ
B26: ОТЧЁТ О СОВОКУПНОМ ДОХОДЕ | D26: #VALUE! | H26: ОТЧЁТ О СОВОКУПНОМ ДОХОДЕ | J26: #VALUE!
B27: в миллионах южноафриканских рэнд | C27: За год, закончившийся 31 декабря | H27: в миллионах долларов США (пересчёт по среднегодовому курсу) | I27: За год, закончившийся 31 декабря
C28: 2021 | D28: 2022 | E28: 2023 | F28: 2024 | I28: 2021 | J28: 2022 | K28: 2023 | L28: 2024
B29: Прибыль за год | C29: 79021 | D29: 49296 | E29: 13446 | F29: 7393 | H29: Прибыль за год | I29: =C29/$O$16 -> 5131.2338 | J29: =D29/$O$15 -> 3238.8962 | K29: =E29/$O$14 -> 756.66854 | L29: =F29/$O$13 -> 395.13629
B30: Статьи, которые реклассифицированы или впоследствии могут быть реклассифицированы в состав прибыли или убытка: | C30: 712 | D30: 792 | E30: 2206 | F30: 308 | H30: Статьи, которые реклассифицированы или впоследствии могут быть реклассифицированы в состав прибыли или убытка: | I30: =C30/$O$16 -> 46.233766 | J30: =D30/$O$15 -> 52.036794 | K30: =E30/$O$14 -> 124.14181 | L30: =F30/$O$13 -> 16.461785
B31: Прибыль от пересчета иностранной валюты | C31: 712 | D31: 792 | E31: 2206 | F31: 308 | H31: Прибыль от пересчета иностранной валюты | I31: =C31/$O$16 -> 46.233766 | J31: =D31/$O$15 -> 52.036794 | K31: =E31/$O$14 -> 124.14181 | L31: =F31/$O$13 -> 16.461785
